[2022-09-16T22:55:38.685+0000] {taskinstance.py:1171} INFO - Dependencies all met for <TaskInstance: data_ingestion_gcs_dag.local_to_gcs_task manual__2022-09-16T22:55:32.193132+00:00 [queued]>
[2022-09-16T22:55:38.697+0000] {taskinstance.py:1171} INFO - Dependencies all met for <TaskInstance: data_ingestion_gcs_dag.local_to_gcs_task manual__2022-09-16T22:55:32.193132+00:00 [queued]>
[2022-09-16T22:55:38.699+0000] {taskinstance.py:1368} INFO - 
--------------------------------------------------------------------------------
[2022-09-16T22:55:38.700+0000] {taskinstance.py:1369} INFO - Starting attempt 1 of 2
[2022-09-16T22:55:38.701+0000] {taskinstance.py:1370} INFO - 
--------------------------------------------------------------------------------
[2022-09-16T22:55:38.717+0000] {taskinstance.py:1389} INFO - Executing <Task(PythonOperator): local_to_gcs_task> on 2022-09-16 22:55:32.193132+00:00
[2022-09-16T22:55:38.725+0000] {standard_task_runner.py:52} INFO - Started process 920 to run task
[2022-09-16T22:55:38.729+0000] {standard_task_runner.py:79} INFO - Running: ['***', 'tasks', 'run', 'data_ingestion_gcs_dag', 'local_to_gcs_task', 'manual__2022-09-16T22:55:32.193132+00:00', '--job-id', '19', '--raw', '--subdir', 'DAGS_FOLDER/data_ingestion_gcs_dag.py', '--cfg-path', '/tmp/tmpe9i_6pyh', '--error-file', '/tmp/tmpi2nfbgtj']
[2022-09-16T22:55:38.732+0000] {standard_task_runner.py:80} INFO - Job 19: Subtask local_to_gcs_task
[2022-09-16T22:55:38.811+0000] {task_command.py:371} INFO - Running <TaskInstance: data_ingestion_gcs_dag.local_to_gcs_task manual__2022-09-16T22:55:32.193132+00:00 [running]> on host e15101bea996
[2022-09-16T22:55:38.896+0000] {taskinstance.py:1583} INFO - Exporting the following env vars:
AIRFLOW_CTX_DAG_OWNER=***
AIRFLOW_CTX_DAG_ID=data_ingestion_gcs_dag
AIRFLOW_CTX_TASK_ID=local_to_gcs_task
AIRFLOW_CTX_EXECUTION_DATE=2022-09-16T22:55:32.193132+00:00
AIRFLOW_CTX_TRY_NUMBER=1
AIRFLOW_CTX_DAG_RUN_ID=manual__2022-09-16T22:55:32.193132+00:00
[2022-09-16T22:55:38.899+0000] {taskinstance.py:1902} ERROR - Task failed with exception
Traceback (most recent call last):
  File "/home/airflow/.local/lib/python3.7/site-packages/airflow/operators/python.py", line 171, in execute
    return_value = self.execute_callable()
  File "/home/airflow/.local/lib/python3.7/site-packages/airflow/operators/python.py", line 189, in execute_callable
    return self.python_callable(*self.op_args, **self.op_kwargs)
  File "/opt/airflow/dags/data_ingestion_gcs_dag.py", line 44, in upload_to_gcs
    client = storage.Client()
  File "/home/airflow/.local/lib/python3.7/site-packages/google/cloud/storage/client.py", line 128, in __init__
    _http=_http,
  File "/home/airflow/.local/lib/python3.7/site-packages/google/cloud/client/__init__.py", line 320, in __init__
    _ClientProjectMixin.__init__(self, project=project, credentials=credentials)
  File "/home/airflow/.local/lib/python3.7/site-packages/google/cloud/client/__init__.py", line 268, in __init__
    project = self._determine_default(project)
  File "/home/airflow/.local/lib/python3.7/site-packages/google/cloud/client/__init__.py", line 287, in _determine_default
    return _determine_default_project(project)
  File "/home/airflow/.local/lib/python3.7/site-packages/google/cloud/_helpers/__init__.py", line 152, in _determine_default_project
    _, project = google.auth.default()
  File "/home/airflow/.local/lib/python3.7/site-packages/google/auth/_default.py", line 583, in default
    credentials, project_id = checker()
  File "/home/airflow/.local/lib/python3.7/site-packages/google/auth/_default.py", line 576, in <lambda>
    lambda: _get_explicit_environ_credentials(quota_project_id=quota_project_id),
  File "/home/airflow/.local/lib/python3.7/site-packages/google/auth/_default.py", line 226, in _get_explicit_environ_credentials
    os.environ[environment_vars.CREDENTIALS], quota_project_id=quota_project_id
  File "/home/airflow/.local/lib/python3.7/site-packages/google/auth/_default.py", line 120, in load_credentials_from_file
    "File {} was not found.".format(filename)
google.auth.exceptions.DefaultCredentialsError: File /.google/credentials/google_credentials.json was not found.
[2022-09-16T22:55:38.913+0000] {taskinstance.py:1412} INFO - Marking task as UP_FOR_RETRY. dag_id=data_ingestion_gcs_dag, task_id=local_to_gcs_task, execution_date=20220916T225532, start_date=20220916T225538, end_date=20220916T225538
[2022-09-16T22:55:38.925+0000] {standard_task_runner.py:97} ERROR - Failed to execute job 19 for task local_to_gcs_task (File /.google/credentials/google_credentials.json was not found.; 920)
[2022-09-16T22:55:38.942+0000] {local_task_job.py:156} INFO - Task exited with return code 1
[2022-09-16T22:55:38.990+0000] {local_task_job.py:279} INFO - 0 downstream tasks scheduled from follow-on schedule check
