[2022-09-17T13:56:33.855+0000] {taskinstance.py:1171} INFO - Dependencies all met for <TaskInstance: data_ingestion_gcs_dag.download_Dataset_task manual__2022-09-17T13:56:31.790771+00:00 [queued]>
[2022-09-17T13:56:33.872+0000] {taskinstance.py:1171} INFO - Dependencies all met for <TaskInstance: data_ingestion_gcs_dag.download_Dataset_task manual__2022-09-17T13:56:31.790771+00:00 [queued]>
[2022-09-17T13:56:33.873+0000] {taskinstance.py:1368} INFO - 
--------------------------------------------------------------------------------
[2022-09-17T13:56:33.877+0000] {taskinstance.py:1369} INFO - Starting attempt 1 of 2
[2022-09-17T13:56:33.878+0000] {taskinstance.py:1370} INFO - 
--------------------------------------------------------------------------------
[2022-09-17T13:56:33.899+0000] {taskinstance.py:1389} INFO - Executing <Task(PythonOperator): download_Dataset_task> on 2022-09-17 13:56:31.790771+00:00
[2022-09-17T13:56:33.910+0000] {standard_task_runner.py:52} INFO - Started process 146 to run task
[2022-09-17T13:56:33.914+0000] {standard_task_runner.py:79} INFO - Running: ['***', 'tasks', 'run', 'data_ingestion_gcs_dag', 'download_Dataset_task', 'manual__2022-09-17T13:56:31.790771+00:00', '--job-id', '67', '--raw', '--subdir', 'DAGS_FOLDER/data_ingestion_gcs_dag.py', '--cfg-path', '/tmp/tmpblws6gy8', '--error-file', '/tmp/tmpjphqek5d']
[2022-09-17T13:56:33.917+0000] {standard_task_runner.py:80} INFO - Job 67: Subtask download_Dataset_task
[2022-09-17T13:56:34.002+0000] {task_command.py:371} INFO - Running <TaskInstance: data_ingestion_gcs_dag.download_Dataset_task manual__2022-09-17T13:56:31.790771+00:00 [running]> on host 9071d3605dea
[2022-09-17T13:56:34.091+0000] {taskinstance.py:1583} INFO - Exporting the following env vars:
AIRFLOW_CTX_DAG_OWNER=***
AIRFLOW_CTX_DAG_ID=data_ingestion_gcs_dag
AIRFLOW_CTX_TASK_ID=download_Dataset_task
AIRFLOW_CTX_EXECUTION_DATE=2022-09-17T13:56:31.790771+00:00
AIRFLOW_CTX_TRY_NUMBER=1
AIRFLOW_CTX_DAG_RUN_ID=manual__2022-09-17T13:56:31.790771+00:00
[2022-09-17T13:56:34.095+0000] {taskinstance.py:1902} ERROR - Task failed with exception
Traceback (most recent call last):
  File "/home/airflow/.local/lib/python3.7/site-packages/airflow/operators/python.py", line 171, in execute
    return_value = self.execute_callable()
  File "/home/airflow/.local/lib/python3.7/site-packages/airflow/operators/python.py", line 189, in execute_callable
    return self.python_callable(*self.op_args, **self.op_kwargs)
  File "/opt/airflow/dags/data_ingestion_gcs_dag.py", line 28, in download_from_drive
    gdown.download(url, output, quiet=False)
  File "/home/airflow/.local/lib/python3.7/site-packages/gdown/download.py", line 120, in download
    os.makedirs(cache_dir)
  File "/usr/local/lib/python3.7/os.py", line 223, in makedirs
    mkdir(name, mode)
PermissionError: [Errno 13] Permission denied: '/home/airflow/.cache/gdown'
[2022-09-17T13:56:34.116+0000] {taskinstance.py:1412} INFO - Marking task as UP_FOR_RETRY. dag_id=data_ingestion_gcs_dag, task_id=download_Dataset_task, execution_date=20220917T135631, start_date=20220917T135633, end_date=20220917T135634
[2022-09-17T13:56:34.129+0000] {standard_task_runner.py:97} ERROR - Failed to execute job 67 for task download_Dataset_task ([Errno 13] Permission denied: '/home/airflow/.cache/gdown'; 146)
[2022-09-17T13:56:34.169+0000] {local_task_job.py:156} INFO - Task exited with return code 1
[2022-09-17T13:56:34.221+0000] {local_task_job.py:279} INFO - 0 downstream tasks scheduled from follow-on schedule check
