[2022-09-17T17:35:30.437+0000] {taskinstance.py:1171} INFO - Dependencies all met for <TaskInstance: data_ingestion_gcs_dag.download_Dataset_task manual__2022-09-17T13:56:31.790771+00:00 [queued]>
[2022-09-17T17:35:30.454+0000] {taskinstance.py:1171} INFO - Dependencies all met for <TaskInstance: data_ingestion_gcs_dag.download_Dataset_task manual__2022-09-17T13:56:31.790771+00:00 [queued]>
[2022-09-17T17:35:30.457+0000] {taskinstance.py:1368} INFO - 
--------------------------------------------------------------------------------
[2022-09-17T17:35:30.458+0000] {taskinstance.py:1369} INFO - Starting attempt 2 of 2
[2022-09-17T17:35:30.460+0000] {taskinstance.py:1370} INFO - 
--------------------------------------------------------------------------------
[2022-09-17T17:35:30.505+0000] {taskinstance.py:1389} INFO - Executing <Task(PythonOperator): download_Dataset_task> on 2022-09-17 13:56:31.790771+00:00
[2022-09-17T17:35:30.522+0000] {standard_task_runner.py:52} INFO - Started process 66 to run task
[2022-09-17T17:35:30.534+0000] {standard_task_runner.py:79} INFO - Running: ['***', 'tasks', 'run', 'data_ingestion_gcs_dag', 'download_Dataset_task', 'manual__2022-09-17T13:56:31.790771+00:00', '--job-id', '70', '--raw', '--subdir', 'DAGS_FOLDER/data_ingestion_gcs_dag.py', '--cfg-path', '/tmp/tmp2looyr24', '--error-file', '/tmp/tmpouukihc0']
[2022-09-17T17:35:30.543+0000] {standard_task_runner.py:80} INFO - Job 70: Subtask download_Dataset_task
[2022-09-17T17:35:30.753+0000] {task_command.py:371} INFO - Running <TaskInstance: data_ingestion_gcs_dag.download_Dataset_task manual__2022-09-17T13:56:31.790771+00:00 [running]> on host 62bee0f86eda
[2022-09-17T17:35:30.944+0000] {taskinstance.py:1583} INFO - Exporting the following env vars:
AIRFLOW_CTX_DAG_OWNER=***
AIRFLOW_CTX_DAG_ID=data_ingestion_gcs_dag
AIRFLOW_CTX_TASK_ID=download_Dataset_task
AIRFLOW_CTX_EXECUTION_DATE=2022-09-17T13:56:31.790771+00:00
AIRFLOW_CTX_TRY_NUMBER=2
AIRFLOW_CTX_DAG_RUN_ID=manual__2022-09-17T13:56:31.790771+00:00
[2022-09-17T17:35:30.948+0000] {taskinstance.py:1902} ERROR - Task failed with exception
Traceback (most recent call last):
  File "/home/airflow/.local/lib/python3.7/site-packages/airflow/operators/python.py", line 171, in execute
    return_value = self.execute_callable()
  File "/home/airflow/.local/lib/python3.7/site-packages/airflow/operators/python.py", line 189, in execute_callable
    return self.python_callable(*self.op_args, **self.op_kwargs)
  File "/opt/airflow/dags/data_ingestion_gcs_dag.py", line 28, in download_from_drive
    gdown.download(url, output, quiet=False)
  File "/home/airflow/.local/lib/python3.7/site-packages/gdown/download.py", line 120, in download
    os.makedirs(cache_dir)
  File "/usr/local/lib/python3.7/os.py", line 223, in makedirs
    mkdir(name, mode)
PermissionError: [Errno 13] Permission denied: '/home/airflow/.cache/gdown'
[2022-09-17T17:35:30.967+0000] {taskinstance.py:1412} INFO - Marking task as FAILED. dag_id=data_ingestion_gcs_dag, task_id=download_Dataset_task, execution_date=20220917T135631, start_date=20220917T173530, end_date=20220917T173530
[2022-09-17T17:35:30.995+0000] {standard_task_runner.py:97} ERROR - Failed to execute job 70 for task download_Dataset_task ([Errno 13] Permission denied: '/home/airflow/.cache/gdown'; 66)
[2022-09-17T17:35:31.035+0000] {local_task_job.py:156} INFO - Task exited with return code 1
[2022-09-17T17:35:31.115+0000] {local_task_job.py:279} INFO - 0 downstream tasks scheduled from follow-on schedule check
