[2022-09-16T23:14:17.694+0000] {taskinstance.py:1171} INFO - Dependencies all met for <TaskInstance: data_ingestion_gcs_dag.local_to_gcs_task manual__2022-09-16T23:14:10.043952+00:00 [queued]>
[2022-09-16T23:14:17.708+0000] {taskinstance.py:1171} INFO - Dependencies all met for <TaskInstance: data_ingestion_gcs_dag.local_to_gcs_task manual__2022-09-16T23:14:10.043952+00:00 [queued]>
[2022-09-16T23:14:17.709+0000] {taskinstance.py:1368} INFO - 
--------------------------------------------------------------------------------
[2022-09-16T23:14:17.710+0000] {taskinstance.py:1369} INFO - Starting attempt 1 of 2
[2022-09-16T23:14:17.712+0000] {taskinstance.py:1370} INFO - 
--------------------------------------------------------------------------------
[2022-09-16T23:14:17.729+0000] {taskinstance.py:1389} INFO - Executing <Task(PythonOperator): local_to_gcs_task> on 2022-09-16 23:14:10.043952+00:00
[2022-09-16T23:14:17.738+0000] {standard_task_runner.py:52} INFO - Started process 114 to run task
[2022-09-16T23:14:17.742+0000] {standard_task_runner.py:79} INFO - Running: ['***', 'tasks', 'run', 'data_ingestion_gcs_dag', 'local_to_gcs_task', 'manual__2022-09-16T23:14:10.043952+00:00', '--job-id', '35', '--raw', '--subdir', 'DAGS_FOLDER/data_ingestion_gcs_dag.py', '--cfg-path', '/tmp/tmpy5xdhs3f', '--error-file', '/tmp/tmp4dln2559']
[2022-09-16T23:14:17.744+0000] {standard_task_runner.py:80} INFO - Job 35: Subtask local_to_gcs_task
[2022-09-16T23:14:17.825+0000] {task_command.py:371} INFO - Running <TaskInstance: data_ingestion_gcs_dag.local_to_gcs_task manual__2022-09-16T23:14:10.043952+00:00 [running]> on host 6f8e2375011a
[2022-09-16T23:14:17.920+0000] {taskinstance.py:1583} INFO - Exporting the following env vars:
AIRFLOW_CTX_DAG_OWNER=***
AIRFLOW_CTX_DAG_ID=data_ingestion_gcs_dag
AIRFLOW_CTX_TASK_ID=local_to_gcs_task
AIRFLOW_CTX_EXECUTION_DATE=2022-09-16T23:14:10.043952+00:00
AIRFLOW_CTX_TRY_NUMBER=1
AIRFLOW_CTX_DAG_RUN_ID=manual__2022-09-16T23:14:10.043952+00:00
[2022-09-16T23:14:17.961+0000] {taskinstance.py:1902} ERROR - Task failed with exception
Traceback (most recent call last):
  File "/home/airflow/.local/lib/python3.7/site-packages/airflow/operators/python.py", line 171, in execute
    return_value = self.execute_callable()
  File "/home/airflow/.local/lib/python3.7/site-packages/airflow/operators/python.py", line 189, in execute_callable
    return self.python_callable(*self.op_args, **self.op_kwargs)
  File "/opt/airflow/dags/data_ingestion_gcs_dag.py", line 45, in upload_to_gcs
    bucket = client.bukcet(bucket)
AttributeError: 'Client' object has no attribute 'bukcet'
[2022-09-16T23:14:17.986+0000] {taskinstance.py:1412} INFO - Marking task as UP_FOR_RETRY. dag_id=data_ingestion_gcs_dag, task_id=local_to_gcs_task, execution_date=20220916T231410, start_date=20220916T231417, end_date=20220916T231417
[2022-09-16T23:14:18.038+0000] {standard_task_runner.py:97} ERROR - Failed to execute job 35 for task local_to_gcs_task ('Client' object has no attribute 'bukcet'; 114)
[2022-09-16T23:14:18.093+0000] {local_task_job.py:156} INFO - Task exited with return code 1
[2022-09-16T23:14:18.142+0000] {local_task_job.py:279} INFO - 0 downstream tasks scheduled from follow-on schedule check
